
[2022-10-11 12:18:35,059]\tINFO\t[Collector.py:Colec:116]\t>> API OriginalData Request..

[2022-10-11 12:18:35,059]\tINFO\t[Collector.py:Colec:116]\t>> API OriginalData Request..

[2022-10-11 12:18:42,153]\tINFO\t[Collector.py:Colec:123]\t>> stat : NORMAL SERVICE.

[2022-10-11 12:18:42,153]\tINFO\t[Collector.py:Colec:123]\t>> stat : NORMAL SERVICE.

[2022-10-11 12:18:42,155]\tDEBUG\t[Collector.py:Colec:124]\t>> statCode : 00

[2022-10-11 12:18:42,155]\tDEBUG\t[Collector.py:Colec:124]\t>> statCode : 00

[2022-10-11 12:18:48,057]\tDEBUG\t[Collector.py:Colec:148]\t>> DB Connect!

[2022-10-11 12:18:48,057]\tDEBUG\t[Collector.py:Colec:148]\t>> DB Connect!

[2022-10-11 12:18:49,220]\tDEBUG\t[Collector.py:Colec:152]\t>> DB APPEND COMPLETE!

[2022-10-11 12:18:49,220]\tDEBUG\t[Collector.py:Colec:152]\t>> DB APPEND COMPLETE!

[2022-10-11 12:19:33,243]\tINFO\t[Collector.py:Colec:116]\t>> API OriginalData Request..

[2022-10-11 12:19:41,384]\tINFO\t[Collector.py:Colec:123]\t>> stat : NORMAL SERVICE.

[2022-10-11 12:19:41,386]\tDEBUG\t[Collector.py:Colec:124]\t>> statCode : 00

[2022-10-11 12:19:47,039]\tDEBUG\t[Collector.py:Colec:148]\t>> DB Connect!

[2022-10-11 12:19:47,982]\tDEBUG\t[Collector.py:Colec:152]\t>> DB APPEND COMPLETE!

[2022-10-11 12:23:20,512]\tINFO\t[Collector.py:Colec:116]\t>> API OriginalData Request..

[2022-10-11 12:23:28,867]\tINFO\t[Collector.py:Colec:123]\t>> stat : NORMAL SERVICE.

[2022-10-11 12:23:28,869]\tDEBUG\t[Collector.py:Colec:124]\t>> statCode : 00

[2022-10-11 12:23:34,717]\tDEBUG\t[Collector.py:Colec:148]\t>> DB Connect!

[2022-10-11 12:23:35,839]\tDEBUG\t[Collector.py:Colec:152]\t>> DB APPEND COMPLETE!

[2022-10-11 12:24:15,640]\tERROR\t[Logger.py:handle_exception:35]\t>> Unexpected exception
Traceback (most recent call last):
  File "D:/MILAB_PJ/ev_data_Collector/main.py", line 11, in <module>
    Collector.Colec(9999, 29, "DB", 1)
TypeError: Colec() takes 3 positional arguments but 4 were given

[2022-10-11 12:24:40,307]\tINFO\t[Collector.py:Colec:116]\t>> API OriginalData Request..

[2022-10-11 12:24:40,315]\tERROR\t[Logger.py:handle_exception:35]\t>> Unexpected exception
Traceback (most recent call last):
  File "D:/MILAB_PJ/ev_data_Collector/main.py", line 11, in <module>
    Collector.Colec(9999, 29, "DB")
  File "D:\MILAB_PJ\ev_data_Collector\Collector.py", line 119, in Colec
    response = requests.get(usrl, params=params)
NameError: name 'usrl' is not defined

[2022-10-11 12:25:06,848]\tINFO\t[Collector.py:Colec:116]\t>> API OriginalData Request..

[2022-10-11 12:25:17,330]\tINFO\t[Collector.py:Colec:123]\t>> stat : NORMAL SERVICE.

[2022-10-11 12:25:17,332]\tDEBUG\t[Collector.py:Colec:124]\t>> statCode : 00

[2022-10-11 12:25:22,734]\tDEBUG\t[Collector.py:Colec:148]\t>> DB Connect!

[2022-10-11 12:25:22,736]\tERROR\t[Logger.py:handle_exception:35]\t>> Unexpected exception
Traceback (most recent call last):
  File "D:/MILAB_PJ/ev_data_Collector/main.py", line 11, in <module>
    Collector.Colec(9999, 29, "DB")
  File "D:\MILAB_PJ\ev_data_Collector\Collector.py", line 151, in Colec
    dfs.to_sql(name=current_time, con=db_connection, if_exists='append',index=False)
NameError: name 'dfs' is not defined

[2022-10-12 01:59:57,195]\tINFO\t[Collector.py:Colec:117]\t>> API OriginalData Request..

[2022-10-12 02:00:03,294]\tINFO\t[Collector.py:Colec:124]\t>> stat : NORMAL SERVICE.

[2022-10-12 02:00:03,296]\tDEBUG\t[Collector.py:Colec:125]\t>> statCode : 00

[2022-10-12 02:00:09,163]\tDEBUG\t[Collector.py:Colec:149]\t>> DB Connect!

[2022-10-12 02:00:09,930]\tDEBUG\t[Collector.py:Colec:153]\t>> DB APPEND COMPLETE!

[2022-10-12 03:32:51,889]\tINFO\t[Collector.py:Colec:117]\t>> API OriginalData Request..

[2022-10-12 03:32:52,515]\tINFO\t[Collector.py:Colec:124]\t>> stat : NORMAL SERVICE.

[2022-10-12 03:32:52,517]\tDEBUG\t[Collector.py:Colec:125]\t>> statCode : 00

[2022-10-12 03:32:54,897]\tERROR\t[Logger.py:handle_exception:35]\t>> Unexpected exception
Traceback (most recent call last):
  File "C:\Users\leedongyub\anaconda3\lib\site-packages\pymysql\connections.py", line 613, in connect
    sock = socket.create_connection(
  File "C:\Users\leedongyub\anaconda3\lib\socket.py", line 787, in create_connection
    for res in getaddrinfo(host, port, 0, SOCK_STREAM):
  File "C:\Users\leedongyub\anaconda3\lib\socket.py", line 918, in getaddrinfo
    for res in _socket.getaddrinfo(host, port, family, type, proto, flags):
socket.gaierror: [Errno 11001] getaddrinfo failed

During handling of the above exception, another exception occurred:

Traceback (most recent call last):
  File "C:\Users\leedongyub\anaconda3\lib\site-packages\sqlalchemy\engine\base.py", line 3256, in _wrap_pool_connect
    return fn()
  File "C:\Users\leedongyub\anaconda3\lib\site-packages\sqlalchemy\pool\base.py", line 310, in connect
    return _ConnectionFairy._checkout(self)
  File "C:\Users\leedongyub\anaconda3\lib\site-packages\sqlalchemy\pool\base.py", line 868, in _checkout
    fairy = _ConnectionRecord.checkout(pool)
  File "C:\Users\leedongyub\anaconda3\lib\site-packages\sqlalchemy\pool\base.py", line 476, in checkout
    rec = pool._do_get()
  File "C:\Users\leedongyub\anaconda3\lib\site-packages\sqlalchemy\pool\impl.py", line 146, in _do_get
    self._dec_overflow()
  File "C:\Users\leedongyub\anaconda3\lib\site-packages\sqlalchemy\util\langhelpers.py", line 70, in __exit__
    compat.raise_(
  File "C:\Users\leedongyub\anaconda3\lib\site-packages\sqlalchemy\util\compat.py", line 207, in raise_
    raise exception
  File "C:\Users\leedongyub\anaconda3\lib\site-packages\sqlalchemy\pool\impl.py", line 143, in _do_get
    return self._create_connection()
  File "C:\Users\leedongyub\anaconda3\lib\site-packages\sqlalchemy\pool\base.py", line 256, in _create_connection
    return _ConnectionRecord(self)
  File "C:\Users\leedongyub\anaconda3\lib\site-packages\sqlalchemy\pool\base.py", line 371, in __init__
    self.__connect()
  File "C:\Users\leedongyub\anaconda3\lib\site-packages\sqlalchemy\pool\base.py", line 666, in __connect
    pool.logger.debug("Error on connect(): %s", e)
  File "C:\Users\leedongyub\anaconda3\lib\site-packages\sqlalchemy\util\langhelpers.py", line 70, in __exit__
    compat.raise_(
  File "C:\Users\leedongyub\anaconda3\lib\site-packages\sqlalchemy\util\compat.py", line 207, in raise_
    raise exception
  File "C:\Users\leedongyub\anaconda3\lib\site-packages\sqlalchemy\pool\base.py", line 661, in __connect
    self.dbapi_connection = connection = pool._invoke_creator(self)
  File "C:\Users\leedongyub\anaconda3\lib\site-packages\sqlalchemy\engine\create.py", line 590, in connect
    return dialect.connect(*cargs, **cparams)
  File "C:\Users\leedongyub\anaconda3\lib\site-packages\sqlalchemy\engine\default.py", line 597, in connect
    return self.dbapi.connect(*cargs, **cparams)
  File "C:\Users\leedongyub\anaconda3\lib\site-packages\pymysql\connections.py", line 353, in __init__
    self.connect()
  File "C:\Users\leedongyub\anaconda3\lib\site-packages\pymysql\connections.py", line 664, in connect
    raise exc
pymysql.err.OperationalError: (2003, "Can't connect to MySQL server on '29' ([Errno 11001] getaddrinfo failed)")

The above exception was the direct cause of the following exception:

Traceback (most recent call last):
  File "D:/MILAB_PJ/ev_data_Collector/main.py", line 22, in <module>
    Collector.Colec(data, zCode, db)
  File "D:\MILAB_PJ\ev_data_Collector\Collector.py", line 149, in Colec
    conn = db_connection.connect()
  File "C:\Users\leedongyub\anaconda3\lib\site-packages\sqlalchemy\engine\base.py", line 3210, in connect
    return self._connection_cls(self, close_with_result=close_with_result)
  File "C:\Users\leedongyub\anaconda3\lib\site-packages\sqlalchemy\engine\base.py", line 96, in __init__
    else engine.raw_connection()
  File "C:\Users\leedongyub\anaconda3\lib\site-packages\sqlalchemy\engine\base.py", line 3289, in raw_connection
    return self._wrap_pool_connect(self.pool.connect, _connection)
  File "C:\Users\leedongyub\anaconda3\lib\site-packages\sqlalchemy\engine\base.py", line 3259, in _wrap_pool_connect
    Connection._handle_dbapi_exception_noconnection(
  File "C:\Users\leedongyub\anaconda3\lib\site-packages\sqlalchemy\engine\base.py", line 2106, in _handle_dbapi_exception_noconnection
    util.raise_(
  File "C:\Users\leedongyub\anaconda3\lib\site-packages\sqlalchemy\util\compat.py", line 207, in raise_
    raise exception
  File "C:\Users\leedongyub\anaconda3\lib\site-packages\sqlalchemy\engine\base.py", line 3256, in _wrap_pool_connect
    return fn()
  File "C:\Users\leedongyub\anaconda3\lib\site-packages\sqlalchemy\pool\base.py", line 310, in connect
    return _ConnectionFairy._checkout(self)
  File "C:\Users\leedongyub\anaconda3\lib\site-packages\sqlalchemy\pool\base.py", line 868, in _checkout
    fairy = _ConnectionRecord.checkout(pool)
  File "C:\Users\leedongyub\anaconda3\lib\site-packages\sqlalchemy\pool\base.py", line 476, in checkout
    rec = pool._do_get()
  File "C:\Users\leedongyub\anaconda3\lib\site-packages\sqlalchemy\pool\impl.py", line 146, in _do_get
    self._dec_overflow()
  File "C:\Users\leedongyub\anaconda3\lib\site-packages\sqlalchemy\util\langhelpers.py", line 70, in __exit__
    compat.raise_(
  File "C:\Users\leedongyub\anaconda3\lib\site-packages\sqlalchemy\util\compat.py", line 207, in raise_
    raise exception
  File "C:\Users\leedongyub\anaconda3\lib\site-packages\sqlalchemy\pool\impl.py", line 143, in _do_get
    return self._create_connection()
  File "C:\Users\leedongyub\anaconda3\lib\site-packages\sqlalchemy\pool\base.py", line 256, in _create_connection
    return _ConnectionRecord(self)
  File "C:\Users\leedongyub\anaconda3\lib\site-packages\sqlalchemy\pool\base.py", line 371, in __init__
    self.__connect()
  File "C:\Users\leedongyub\anaconda3\lib\site-packages\sqlalchemy\pool\base.py", line 666, in __connect
    pool.logger.debug("Error on connect(): %s", e)
  File "C:\Users\leedongyub\anaconda3\lib\site-packages\sqlalchemy\util\langhelpers.py", line 70, in __exit__
    compat.raise_(
  File "C:\Users\leedongyub\anaconda3\lib\site-packages\sqlalchemy\util\compat.py", line 207, in raise_
    raise exception
  File "C:\Users\leedongyub\anaconda3\lib\site-packages\sqlalchemy\pool\base.py", line 661, in __connect
    self.dbapi_connection = connection = pool._invoke_creator(self)
  File "C:\Users\leedongyub\anaconda3\lib\site-packages\sqlalchemy\engine\create.py", line 590, in connect
    return dialect.connect(*cargs, **cparams)
  File "C:\Users\leedongyub\anaconda3\lib\site-packages\sqlalchemy\engine\default.py", line 597, in connect
    return self.dbapi.connect(*cargs, **cparams)
  File "C:\Users\leedongyub\anaconda3\lib\site-packages\pymysql\connections.py", line 353, in __init__
    self.connect()
  File "C:\Users\leedongyub\anaconda3\lib\site-packages\pymysql\connections.py", line 664, in connect
    raise exc
sqlalchemy.exc.OperationalError: (pymysql.err.OperationalError) (2003, "Can't connect to MySQL server on '29' ([Errno 11001] getaddrinfo failed)")
(Background on this error at: https://sqlalche.me/e/14/e3q8)

[2022-10-12 03:33:44,012]\tINFO\t[Collector.py:Colec:117]\t>> API OriginalData Request..

[2022-10-12 03:33:50,696]\tINFO\t[Collector.py:Colec:124]\t>> stat : NORMAL SERVICE.

[2022-10-12 03:33:50,698]\tDEBUG\t[Collector.py:Colec:125]\t>> statCode : 00

[2022-10-12 03:33:59,051]\tDEBUG\t[Collector.py:Colec:150]\t>> DB Connect!

[2022-10-12 03:33:59,816]\tDEBUG\t[Collector.py:Colec:154]\t>> DB APPEND COMPLETE!

[2022-10-12 03:33:59,825]\tERROR\t[Logger.py:handle_exception:35]\t>> Unexpected exception
Traceback (most recent call last):
  File "D:/MILAB_PJ/ev_data_Collector/main.py", line 23, in <module>
    time.sleep(time)
AttributeError: 'str' object has no attribute 'sleep'

[2022-10-12 03:35:13,372]\tINFO\t[Collector.py:Colec:117]\t>> API OriginalData Request..

[2022-10-12 03:35:18,882]\tINFO\t[Collector.py:Colec:124]\t>> stat : NORMAL SERVICE.

[2022-10-12 03:35:18,883]\tDEBUG\t[Collector.py:Colec:125]\t>> statCode : 00

[2022-10-12 03:35:24,837]\tDEBUG\t[Collector.py:Colec:150]\t>> DB Connect!

[2022-10-12 03:35:25,715]\tDEBUG\t[Collector.py:Colec:154]\t>> DB APPEND COMPLETE!

[2022-10-12 03:35:25,725]\tERROR\t[Logger.py:handle_exception:35]\t>> Unexpected exception
Traceback (most recent call last):
  File "D:/MILAB_PJ/ev_data_Collector/main.py", line 23, in <module>
    time.sleep(int(time))
AttributeError: 'str' object has no attribute 'sleep'

[2022-10-12 03:36:45,656]\tINFO\t[Collector.py:Colec:117]\t>> API OriginalData Request..

[2022-10-12 03:36:51,667]\tINFO\t[Collector.py:Colec:124]\t>> stat : NORMAL SERVICE.

[2022-10-12 03:36:51,669]\tDEBUG\t[Collector.py:Colec:125]\t>> statCode : 00

[2022-10-12 03:36:57,517]\tDEBUG\t[Collector.py:Colec:150]\t>> DB Connect!

[2022-10-12 03:36:58,410]\tDEBUG\t[Collector.py:Colec:154]\t>> DB APPEND COMPLETE!

[2022-10-12 03:37:13,422]\tINFO\t[Collector.py:Colec:117]\t>> API OriginalData Request..

[2022-10-12 03:37:19,771]\tINFO\t[Collector.py:Colec:124]\t>> stat : NORMAL SERVICE.

[2022-10-12 03:37:19,773]\tDEBUG\t[Collector.py:Colec:125]\t>> statCode : 00

[2022-10-12 03:37:25,581]\tDEBUG\t[Collector.py:Colec:150]\t>> DB Connect!

[2022-10-12 03:37:26,411]\tDEBUG\t[Collector.py:Colec:154]\t>> DB APPEND COMPLETE!

[2022-10-12 03:37:41,421]\tINFO\t[Collector.py:Colec:117]\t>> API OriginalData Request..

[2022-10-12 03:37:47,488]\tINFO\t[Collector.py:Colec:124]\t>> stat : NORMAL SERVICE.

[2022-10-12 03:37:47,490]\tDEBUG\t[Collector.py:Colec:125]\t>> statCode : 00

[2022-10-12 03:37:53,728]\tDEBUG\t[Collector.py:Colec:150]\t>> DB Connect!

[2022-10-12 03:37:54,670]\tDEBUG\t[Collector.py:Colec:154]\t>> DB APPEND COMPLETE!
